<?xml version="1.0" encoding="utf-8"?>
<robot
        name="GR1T1">
    <link
            name="base">
        <inertial>
            <origin
                    xyz="-0.0508888422032162 0.000109183466089114 -0.0455794100581443"
                    rpy="0 0 0"/>
            <mass
                    value="6.45116957899581"/>
            <inertia
                    ixx="0.0149278332076571"
                    ixy="1.72607763235119E-05"
                    ixz="-7.0218313084794E-05"
                    iyy="0.00640926461574383"
                    iyz="-3.16385131035405E-06"
                    izz="0.0127995550738519"/>
        </inertial>
        <visual>
            <origin
                    xyz="0 0 0"
                    rpy="0 0 0"/>
            <geometry>
                <mesh
                        filename="../meshes/base.STL"/>
            </geometry>
            <material
                    name="">
                <color
                        rgba="0.752941176470588 0.752941176470588 0.752941176470588 1"/>
            </material>
        </visual>
<!--        <collision>-->
<!--            <origin-->
<!--                    xyz="0 0 0.0"-->
<!--                    rpy="0 0 0"/>-->
<!--            <geometry>-->
<!--                <cylinder length="0.1" radius="0.1"/>-->
<!--            </geometry>-->
<!--        </collision>-->
        <!-- <origin
          xyz="0 0 0"
          rpy="0 0 0" />
        <geometry>
          <mesh
            filename="../meshes/base.STL" />
        </geometry> -->
    </link>
    <link
            name="l_thigh_roll">
        <inertial>
            <origin
                    xyz="0.04163 3.4568E-05 -0.0021382"
                    rpy="0 0 0"/>
            <mass
                    value="1.1437"/>
            <inertia
                    ixx="0.0010239"
                    ixy="9.9505E-08"
                    ixz="5.4748E-05"
                    iyy="0.0009439"
                    iyz="-1.1272E-06"
                    izz="0.0011557"/>
        </inertial>
        <visual>
            <origin
                    xyz="0 0 0"
                    rpy="0 0 0"/>
            <geometry>
                <mesh
                        filename="../meshes/l_thigh_roll.STL"/>
            </geometry>
            <material
                    name="">
                <color
                        rgba="0.75294 0.75294 0.75294 1"/>
            </material>
        </visual>
        <!-- <collision>
          <origin
            xyz="0 0 0"
            rpy="0 0 0" />
          <geometry>
            <mesh
              filename="../meshes/l_thigh_roll.STL" />
          </geometry>
        </collision> -->
    </link>
    <joint
            name="l_hip_roll"
            type="revolute">
        <origin
                xyz="-0.047999 0.105 -0.057493"
                rpy="0 0 0"/>
        <parent
                link="base"/>
        <child
                link="l_thigh_roll"/>
        <axis
                xyz="1 0 1.221E-05"/>
        <limit
                lower="-0.09"
                upper="0.79"
                effort="100"
                velocity="12.15"/>
    </joint>
    <link
            name="l_thigh_yaw">
        <inertial>
            <origin
                    xyz="0.00018348 0.046462 -0.10389"
                    rpy="0 0 0"/>
            <mass
                    value="3.9888"/>
            <inertia
                    ixx="0.010009"
                    ixy="-4.6866E-05"
                    ixz="7.2342E-05"
                    iyy="0.016331"
                    iyz="0.00022608"
                    izz="0.0092577"/>
        </inertial>
        <visual>
            <origin
                    xyz="0 0 0"
                    rpy="0 0 0"/>
            <geometry>
                <mesh
                        filename="../meshes/l_thigh_yaw.STL"/>
            </geometry>
            <material
                    name="">
                <color
                        rgba="0.75294 0.75294 0.75294 1"/>
            </material>
        </visual>
        <!-- <collision>
          <origin
            xyz="0 0 0"
            rpy="0 0 0" />
          <geometry>
            <mesh
              filename="../meshes/l_thigh_yaw.STL" />
          </geometry>
        </collision> -->
    </link>
    <joint
            name="l_hip_yaw"
            type="revolute">
        <origin
                xyz="0.048 0 -0.030499"
                rpy="0 0 0"/>
        <parent
                link="l_thigh_roll"/>
        <child
                link="l_thigh_yaw"/>
        <axis
                xyz="1.2209E-05 6.8349E-05 1"/>
        <limit
                lower="-0.7"
                upper="0.7"
                effort="82.5"
                velocity="16.76"/>
    </joint>
    <link
            name="l_thigh_pitch">
        <inertial>
            <origin
                    xyz="0.0028493 -0.021688 -0.090886"
                    rpy="0 0 0"/>
            <mass
                    value="6.369"/>
            <inertia
                    ixx="0.042477"
                    ixy="1.4561E-05"
                    ixz="0.00097249"
                    iyy="0.053235"
                    iyz="-8.0062E-05"
                    izz="0.013469"/>
        </inertial>
        <visual>
            <origin
                    xyz="0 0 0"
                    rpy="0 0 0"/>
            <geometry>
                <mesh
                        filename="../meshes/l_thigh_pitch.STL"/>
            </geometry>
            <material
                    name="">
                <color
                        rgba="0.75294 0.75294 0.75294 1"/>
            </material>
        </visual>
        <collision>
            <origin
                    xyz="0 0 -0.15"
                    rpy="0 0 0"/>
            <geometry>
                <cylinder length="0.25" radius="0.05"/>
            </geometry>
        </collision>
        <!-- <origin
          xyz="0 0 0"
          rpy="0 0 0" />
        <geometry>
          <mesh
            filename="../meshes/l_thigh_pitch.STL" />
        </geometry> -->
    </link>
    <joint
            name="l_hip_pitch"
            type="revolute">
        <origin
                xyz="0 0 -0.11"
                rpy="0 0 0"/>
        <parent
                link="l_thigh_yaw"/>
        <child
                link="l_thigh_pitch"/>
        <axis
                xyz="0 1 -6.8349E-05"/>
        <limit
                lower="-1.75"
                upper="0.7"
                effort="160"
                velocity="37.38"/>
    </joint>
    <link
            name="l_shank_pitch">
        <inertial>
            <origin
                    xyz="0.0024312 -2.9945E-05 -0.11554"
                    rpy="0 0 0"/>
            <mass
                    value="2.1895"/>
            <inertia
                    ixx="0.016117"
                    ixy="-6.426E-06"
                    ixz="-5.8179E-05"
                    iyy="0.01627"
                    iyz="-2.4143E-06"
                    izz="0.0011365"/>
        </inertial>
        <visual>
            <origin
                    xyz="0 0 0"
                    rpy="0 0 0"/>
            <geometry>
                <mesh
                        filename="../meshes/l_shank_pitch.STL"/>
            </geometry>
            <material
                    name="">
                <color
                        rgba="0.75294 0.75294 0.75294 1"/>
            </material>
        </visual>
        <collision>
            <origin
                    xyz="0 0 -0.15"
                    rpy="0 0 0"/>
            <geometry>
                <cylinder length="0.2" radius="0.05"/>
            </geometry>
        </collision>
        <!-- <origin
          xyz="0 0 0"
          rpy="0 0 0" />
        <geometry>
          <mesh
            filename="../meshes/l_shank_pitch.STL" />
        </geometry> -->
    </link>
    <joint
            name="l_knee_pitch"
            type="revolute">
        <origin
                xyz="0 2.4606E-05 -0.36"
                rpy="0 0 0"/>
        <parent
                link="l_thigh_pitch"/>
        <child
                link="l_shank_pitch"/>
        <axis
                xyz="0 1 6.8349E-05"/>
        <limit
                lower="-0.09"
                upper="1.92"
                effort="160"
                velocity="37.38"/>
    </joint>
    <link
            name="l_foot_pitch">
        <inertial>
            <origin
                    xyz="1.748E-11 4.3804E-11 -1.1768E-14"
                    rpy="0 0 0"/>
            <mass
                    value="0.080335"/>
            <inertia
                    ixx="5.1022E-06"
                    ixy="-7.7589E-16"
                    ixz="1.1105E-11"
                    iyy="4.3976E-06"
                    iyz="1.4349E-11"
                    izz="4.188E-06"/>
        </inertial>
        <visual>
            <origin
                    xyz="0 0 0"
                    rpy="0 0 0"/>
            <geometry>
                <mesh
                        filename="../meshes/l_foot_pitch.STL"/>
            </geometry>
            <material
                    name="">
                <color
                        rgba="0.75294 0.75294 0.75294 1"/>
            </material>
        </visual>
        <!-- <collision>
          <origin
            xyz="0 0 0"
            rpy="0 0 0" />
          <geometry>
            <mesh
              filename="../meshes/l_foot_pitch.STL" />
          </geometry>
        </collision> -->
    </link>
    <joint
            name="l_ankle_pitch"
            type="revolute">
        <origin
                xyz="0 2.3239E-05 -0.34"
                rpy="0 0 0"/>
        <parent
                link="l_shank_pitch"/>
        <child
                link="l_foot_pitch"/>
        <axis
                xyz="0 1 6.8349E-05"/>
        <limit
                lower="-1.05"
                upper="0.52"
                effort="8"
                velocity="20.32"/>
    </joint>
    <link
            name="l_foot_roll">
        <inertial>
            <origin
                    xyz="0.039446 0.00035757 -0.038101"
                    rpy="0 0 0"/>
            <mass
                    value="0.584"/>
            <inertia
                    ixx="0.00036926"
                    ixy="2.5654E-06"
                    ixz="1.6145E-05"
                    iyy="0.0024027"
                    iyz="-1.171E-06"
                    izz="0.0027102"/>
        </inertial>
        <visual>
            <origin
                    xyz="0 0 0"
                    rpy="0 0 0"/>
            <geometry>
                <mesh
                        filename="../meshes/l_foot_roll.STL"/>
            </geometry>
            <material
                    name="">
                <color
                        rgba="0.75294 0.75294 0.75294 1"/>
            </material>
        </visual>
        <!--        <collision>-->
        <!--            <origin-->
        <!--                    xyz="0 0 0"-->
        <!--                    rpy="0 0 0"/>-->
        <!--            <geometry>-->
        <!--                <mesh-->
        <!--                        filename="../meshes/l_foot_roll.STL"/>-->
        <!--            </geometry>-->
        <!--        </collision>-->
        <collision name="l_foot">
            <origin rpy="0 1.5708 0" xyz="0.05 0.0 -0.035"/>
            <geometry>
                <box size="0.03 0.1 0.24"/>
            </geometry>
        </collision>
<!--        <collision name="l_foot_1">-->
<!--            <origin rpy="0 1.5708 0" xyz="0.05 0.022 -0.035"/>-->
<!--            <geometry>-->
<!--                <cylinder length="0.24" radius="0.02"/>-->
<!--            </geometry>-->
<!--        </collision>-->
<!--        <collision name="l_foot_2">-->
<!--            <origin rpy="0 1.5708 0" xyz="0.05 -0.022 -0.035"/>-->
<!--            <geometry>-->
<!--                <cylinder length="0.24" radius="0.02"/>-->
<!--            </geometry>-->
<!--        </collision>-->
    </link>
    <joint
            name="l_ankle_roll"
            type="revolute">
        <origin
                xyz="0 0 0"
                rpy="0 0 0"/>
        <parent
                link="l_foot_pitch"/>
        <child
                link="l_foot_roll"/>
        <axis
                xyz="1 0 1.221E-05"/>
        <limit
                lower="-0.44"
                upper="0.44"
                effort="3"
                velocity="20.32"/>
    </joint>
    <link
            name="r_thigh_roll">
        <inertial>
            <origin
                    xyz="0.0416295155706895 3.45677738990829E-05 -0.00213823706160741"
                    rpy="0 0 0"/>
            <mass
                    value="1.14366511831048"/>
            <inertia
                    ixx="0.00102394921532563"
                    ixy="9.95085325681151E-08"
                    ixz="5.47475125260362E-05"
                    iyy="0.000943899068816994"
                    iyz="-1.12724702713386E-06"
                    izz="0.00115569508392434"/>
        </inertial>
        <visual>
            <origin
                    xyz="0 0 0"
                    rpy="0 0 0"/>
            <geometry>
                <mesh
                        filename="../meshes/r_thigh_roll.STL"/>
            </geometry>
            <material
                    name="">
                <color
                        rgba="0.752941176470588 0.752941176470588 0.752941176470588 1"/>
            </material>
        </visual>
        <!-- <collision>
          <origin
            xyz="0 0 0"
            rpy="0 0 0" />
          <geometry>
            <mesh
              filename="../meshes/r_thigh_roll.STL" />
          </geometry>
        </collision> -->
    </link>
    <joint
            name="r_hip_roll"
            type="revolute">
        <origin
                xyz="-0.047999 -0.105 -0.057508"
                rpy="0 0 0"/>
        <parent
                link="base"/>
        <child
                link="r_thigh_roll"/>
        <axis
                xyz="1 0 1.221E-05"/>
        <limit
                lower="-0.79"
                upper="0.09"
                effort="100"
                velocity="12.15"/>
    </joint>
    <link
            name="r_thigh_yaw">
        <inertial>
            <origin
                    xyz="-0.00159762056384161 -0.0464481886102113 -0.103898553073221"
                    rpy="0 0 0"/>
            <mass
                    value="3.98881919610613"/>
            <inertia
                    ixx="0.0100089332385704"
                    ixy="6.17707630241845E-05"
                    ixz="6.45577121456205E-05"
                    iyy="0.0163310979398362"
                    iyz="-0.000225113633002584"
                    izz="0.00925763732044222"/>
        </inertial>
        <visual>
            <origin
                    xyz="0 0 0"
                    rpy="0 0 0"/>
            <geometry>
                <mesh
                        filename="../meshes/r_thigh_yaw.STL"/>
            </geometry>
            <material
                    name="">
                <color
                        rgba="0.752941176470588 0.752941176470588 0.752941176470588 1"/>
            </material>
        </visual>
        <!-- <collision>
          <origin
            xyz="0 0 0"
            rpy="0 0 0" />
          <geometry>
            <mesh
              filename="../meshes/r_thigh_yaw.STL" />
          </geometry>
        </collision> -->
    </link>
    <joint
            name="r_hip_yaw"
            type="revolute">
        <origin
                xyz="0.048 0 -0.030499"
                rpy="0 0 0"/>
        <parent
                link="r_thigh_roll"/>
        <child
                link="r_thigh_yaw"/>
        <axis
                xyz="1.2209E-05 6.8349E-05 1"/>
        <limit
                lower="-0.7"
                upper="0.7"
                effort="82.5"
                velocity="16.76"/>
    </joint>
    <link
            name="r_thigh_pitch">
        <inertial>
            <origin
                    xyz="0.00284199593611564 0.021700884823371 -0.0919987122372821"
                    rpy="0 0 0"/>
            <mass
                    value="6.36895320063918"/>
            <inertia
                    ixx="0.0424483438482445"
                    ixy="-1.47927561603623E-05"
                    ixz="0.000984281537641053"
                    iyy="0.0532347537596881"
                    iyz="7.05431175910573E-05"
                    izz="0.013497669133255"/>
        </inertial>
        <visual>
            <origin
                    xyz="0 0 0"
                    rpy="0 0 0"/>
            <geometry>
                <mesh
                        filename="../meshes/r_thigh_pitch.STL"/>
            </geometry>
            <material
                    name="">
                <color
                        rgba="0.752941176470588 0.752941176470588 0.752941176470588 1"/>
            </material>
        </visual>
        <collision>
            <origin
                    xyz="0 0 -0.15"
                    rpy="0 0 0"/>
            <geometry>
                <cylinder length="0.25" radius="0.05"/>
            </geometry>
        </collision>
        <!-- <origin
          xyz="0 0 0"
          rpy="0 0 0" />
        <geometry>
          <mesh
            filename="../meshes/r_thigh_pitch.STL" />
        </geometry> -->
    </link>
    <joint
            name="r_hip_pitch"
            type="revolute">
        <origin
                xyz="0 0 -0.11"
                rpy="0 0 0"/>
        <parent
                link="r_thigh_yaw"/>
        <child
                link="r_thigh_pitch"/>
        <axis
                xyz="0 1 6.8349E-05"/>
        <limit
                lower="-1.75"
                upper="0.7"
                effort="160"
                velocity="37.38"/>
    </joint>
    <link
            name="r_shank_pitch">
        <inertial>
            <origin
                    xyz="0.00236658249661569 4.56188310302558E-05 -0.115531948381968"
                    rpy="0 0 0"/>
            <mass
                    value="2.1894662603365"/>
            <inertia
                    ixx="0.0161181947280801"
                    ixy="5.07999055973116E-06"
                    ixz="-5.80047175383452E-05"
                    iyy="0.0162705809299741"
                    iyz="8.20054646838796E-06"
                    izz="0.001135584923079"/>
        </inertial>
        <visual>
            <origin
                    xyz="0 0 0"
                    rpy="0 0 0"/>
            <geometry>
                <mesh
                        filename="../meshes/r_shank_pitch.STL"/>
            </geometry>
            <material
                    name="">
                <color
                        rgba="0.752941176470588 0.752941176470588 0.752941176470588 1"/>
            </material>
        </visual>
        <collision>
            <origin
                    xyz="0 0 -0.15"
                    rpy="0 0 0"/>
            <geometry>
                <cylinder length="0.2" radius="0.05"/>
            </geometry>
        </collision>
        <!-- <origin
          xyz="0 0 0"
          rpy="0 0 0" />
        <geometry>
          <mesh
            filename="../meshes/r_shank_pitch.STL" />
        </geometry> -->
    </link>
    <joint
            name="r_knee_pitch"
            type="revolute">
        <origin
                xyz="0 2.4606E-05 -0.36"
                rpy="0 0 0"/>
        <parent
                link="r_thigh_pitch"/>
        <child
                link="r_shank_pitch"/>
        <axis
                xyz="0 1 -6.8349E-05"/>
        <limit
                lower="-0.09"
                upper="1.92"
                effort="160"
                velocity="37.38"/>
    </joint>
    <link
            name="r_foot_pitch">
        <inertial>
            <origin
                    xyz="1.75705006100202E-11 4.40342345919831E-11 -1.0991207943789E-14"
                    rpy="0 0 0"/>
            <mass
                    value="0.0799218634469264"/>
            <inertia
                    ixx="5.11122380590824E-06"
                    ixy="-7.90463256918838E-16"
                    ixz="1.13183213108103E-11"
                    iyy="4.40003788346816E-06"
                    iyz="1.50971653307747E-11"
                    izz="4.17953587325444E-06"/>
        </inertial>
        <visual>
            <origin
                    xyz="0 0 0"
                    rpy="0 0 0"/>
            <geometry>
                <mesh
                        filename="../meshes/r_foot_pitch.STL"/>
            </geometry>
            <material
                    name="">
                <color
                        rgba="0.752941176470588 0.752941176470588 0.752941176470588 1"/>
            </material>
        </visual>
        <!-- <collision>
          <origin
            xyz="0 0 0"
            rpy="0 0 0" />
          <geometry>
            <mesh
              filename="../meshes/r_foot_pitch.STL" />
          </geometry>
        </collision> -->
    </link>
    <joint
            name="r_ankle_pitch"
            type="revolute">
        <origin
                xyz="0 2.3239E-05 -0.34"
                rpy="0 0 0"/>
        <parent
                link="r_shank_pitch"/>
        <child
                link="r_foot_pitch"/>
        <axis
                xyz="0 1 6.8349E-05"/>
        <limit
                lower="-1.05"
                upper="0.52"
                effort="8"
                velocity="20.32"/>
    </joint>
    <link
            name="r_foot_roll">
        <inertial>
            <origin
                    xyz="0.043909 -0.00032475 -0.039419"
                    rpy="0 0 0"/>
            <mass
                    value="0.58089"/>
            <inertia
                    ixx="0.00036866"
                    ixy="-2.4583E-06"
                    ixz="2.061E-05"
                    iyy="0.0024886"
                    iyz="1.0326E-06"
                    izz="0.0028008"/>
        </inertial>
        <visual>
            <origin
                    xyz="0 0 0"
                    rpy="0 0 0"/>
            <geometry>
                <mesh
                        filename="../meshes/r_foot_roll.STL"/>
            </geometry>
            <material
                    name="">
                <color
                        rgba="0.75294 0.75294 0.75294 1"/>
            </material>
        </visual>
        <!--        <collision>-->
        <!--            <origin-->
        <!--                    xyz="0 0 0"-->
        <!--                    rpy="0 0 0"/>-->
        <!--            <geometry>-->
        <!--                <mesh-->
        <!--                        filename="../meshes/r_foot_roll.STL"/>-->
        <!--            </geometry>-->
        <!--        </collision>-->
        <collision name="r_foot">
            <origin rpy="0 1.5708 0" xyz="0.05 0.0 -0.035"/>
            <geometry>
                <box size="0.03 0.1 0.24"/>
            </geometry>
        </collision>
<!--        <collision name="r_foot_1">-->
<!--            <origin rpy="0 1.5708 0" xyz="0.05 0.022 -0.035"/>-->
<!--            <geometry>-->
<!--                <cylinder length="0.24" radius="0.02"/>-->
<!--            </geometry>-->
<!--        </collision>-->
<!--        <collision name="r_foot_2">-->
<!--            <origin rpy="0 1.5708 0" xyz="0.05 -0.022 -0.035"/>-->
<!--            <geometry>-->
<!--                <cylinder length="0.24" radius="0.02"/>-->
<!--            </geometry>-->
<!--        </collision>-->
    </link>
    <joint
            name="r_ankle_roll"
            type="revolute">
        <origin
                xyz="0 0 0"
                rpy="0 0 0"/>
        <parent
                link="r_foot_pitch"/>
        <child
                link="r_foot_roll"/>
        <axis
                xyz="1 0 1.221E-05"/>
        <limit
                lower="-0.44"
                upper="0.44"
                effort="3"
                velocity="20.32"/>
    </joint>
    <link
            name="waist_yaw">
        <inertial>
            <origin
                    xyz="-0.01038801904175 -0.0016963578434683 0.0224708834468219"
                    rpy="0 0 0"/>
            <mass
                    value="0.378859790655159"/>
            <inertia
                    ixx="0.000196919706249791"
                    ixy="2.12382402842255E-08"
                    ixz="2.56981032600088E-05"
                    iyy="0.000354992150456574"
                    iyz="2.2415775111576E-10"
                    izz="0.00038367592149874"/>
        </inertial>
        <visual>
            <origin
                    xyz="0 0 0"
                    rpy="0 0 0"/>
            <geometry>
                <mesh
                        filename="../meshes/waist_yaw.STL"/>
            </geometry>
            <material
                    name="">
                <color
                        rgba="0.752941176470588 0.752941176470588 0.752941176470588 1"/>
            </material>
        </visual>
        <!--        <collision>-->
        <!--            <origin-->
        <!--                    xyz="0 0 -0.06"-->
        <!--                    rpy="1.57 0 0"/>-->
        <!--            <geometry>-->
        <!--                <cylinder length="0.29" radius="0.039"/>-->
        <!--            </geometry>-->
        <!--        </collision>-->
        <!--      &lt;!&ndash; <origin-->
        <!--        xyz="0 0 0"-->
        <!--        rpy="0 0 0" />-->
        <!--      <geometry>-->
        <!--        <mesh-->
        <!--          filename="../meshes/waist_yaw.STL" />-->
        <!--      </geometry> &ndash;&gt;-->
    </link>
    <joint
            name="waist_yaw"
            type="revolute">
        <origin
                xyz="0 0 0.0065"
                rpy="0 0 0"/>
        <parent
                link="base"/>
        <child
                link="waist_yaw"/>
        <axis
                xyz="-1.221E-05 -6.8349E-05 1"/>
        <limit
                lower="-1.05"
                upper="1.05"
                effort="82.5"
                velocity="16.76"/>
    </joint>
    <link
            name="waist_pitch">
        <inertial>
            <origin
                    xyz="0.00229172837325653 -0.00229363862540611 0.0425378199809092"
                    rpy="0 0 0"/>
            <mass
                    value="4.40328023801883"/>
            <inertia
                    ixx="0.00487323232531471"
                    ixy="-1.33065018698405E-06"
                    ixz="-4.0266051775557E-05"
                    iyy="0.00486933742500086"
                    iyz="-5.32468490704019E-05"
                    izz="0.00355689827572313"/>
        </inertial>
        <visual>
            <origin
                    xyz="0 0 0"
                    rpy="0 0 0"/>
            <geometry>
                <mesh
                        filename="../meshes/waist_pitch.STL"/>
            </geometry>
            <material
                    name="">
                <color
                        rgba="0.752941176470588 0.752941176470588 0.752941176470588 1"/>
            </material>
        </visual>
        <!-- <collision>
          <origin
            xyz="0 0 0"
            rpy="0 0 0" />
          <geometry>
            <mesh
              filename="../meshes/waist_pitch.STL" />
          </geometry>
        </collision> -->
    </link>
    <joint
            name="waist_pitch"
            type="revolute">
        <origin
                xyz="0 0 0.055"
                rpy="0 0 0"/>
        <parent
                link="waist_yaw"/>
        <child
                link="waist_pitch"/>
        <axis
                xyz="0 1 -6.8349E-05"/>
        <limit
                lower="-0.52"
                upper="1.22"
                effort="82.5"
                velocity="16.76"/>
    </joint>
    <link
            name="waist_roll">
        <inertial>
            <origin
                    xyz="-0.00982804024116587 -1.29539615708683E-05 0.160653030053409"
                    rpy="0 0 0"/>
            <mass
                    value="7.34392576050251"/>
            <inertia
                    ixx="0.03052609429886"
                    ixy="-7.04406839473537E-07"
                    ixz="8.78092229296906E-05"
                    iyy="0.0217567392965276"
                    iyz="2.92528051867509E-07"
                    izz="0.013678748857541"/>
        </inertial>
        <visual>
            <origin
                    xyz="0 0 0"
                    rpy="0 0 0"/>
            <geometry>
                <mesh
                        filename="../meshes/waist_roll.STL"/>
            </geometry>
            <material
                    name="">
                <color
                        rgba="0.752941176470588 0.752941176470588 0.752941176470588 1"/>
            </material>
        </visual>
        <collision>
            <origin
                    xyz="0 0 0.2"
                    rpy="0 0 0"/>
            <geometry>
                <cylinder length="0.25" radius="0.1"/>
            </geometry>
        </collision>
        <!-- <collision>
          <origin
            xyz="0 0 0"
            rpy="0 0 0" />
          <geometry>
            <mesh
              filename="../meshes/waist_roll.STL" />
          </geometry>
        </collision> -->
    </link>
    <joint
            name="waist_roll"
            type="revolute">
        <origin
                xyz="0 0 0.085"
                rpy="0 0 0"/>
        <parent
                link="waist_pitch"/>
        <child
                link="waist_roll"/>
        <axis
                xyz="1 0 1.221E-05"/>
        <limit
                lower="-0.7"
                upper="0.7"
                effort="82.5"
                velocity="16.76"/>
    </joint>

</robot>